Workbook

Sheet 1_PROGRESS PAYMENT
B5: Subcontract Payment Request | H5: SIGN | I5: IN CHARGE | J5: CONS DEPT. | K5: PLN DEPT. | M5: P.M
I7: / / | J7: / / | K7: / / | M7: / /
B10: INVOICE DATE | E10: INVOICE NO | F10: =IF(OR('1_PROGRESS PAYMENT'!$H$12="",'1_PROGRESS PAYMENT'!$C$38=""),"",'1_PROGRESS PAYMENT'!$H$12&"-INV-"&TEXT('1_PROGRESS PAYMENT'!$C$38,"000")) | I10: DUE DATE | M10: ADMIN DEPT.
B12: PROJECT | C12: HL-GA Battery Project | F12: CONTRACT NUMBER
B13: SUBCONTRACTOR | C13: Nahshon MEP | F13: CONTRACT PRICE | H13: ='3_CONTINUATION SHEET'!K41 -> 1789000
B14: SCOPE OF WORKS | C14: Additional Finish Works PKG-7 | F14: P/BOND AMT/EXPIRY | M14: FNC DEPT.
B15: CONTRACT PERIOD | C15: 2026.08 ~ 2026.11 | D15: CONTRACT DATE | F15: AP-BOND AMT/EXPIRY
B16: INSURANCE | F16: W-BOND AMT/EXPIRY
I17: ( Currency : USD )
B18: DESCRIPTION | E18: UP TO PREVIOUS BILL | F18: THIS BILL | G18: UP TO THIS BILL | J18: REMARKS
B19: PAYMENT RECEIVED IN ADVANCE | D19: ① | E19: 0 | F19: =IF(OR(NOT(ISNUMBER(G19)),NOT(ISNUMBER(E19))),"",G19-E19) -> 357800 | G19: 357800 | J19: 0.2
B20: WORKS DONE | C20: WORK DONE | E20: =IF(NOT(ISNUMBER('3_CONTINUATION SHEET'!M41)),"",'3_CONTINUATION SHEET'!M41) -> 0 | F20: =IF(OR(NOT(ISNUMBER(G20)),NOT(ISNUMBER(E20))),"",G20-E20) -> 218000 | G20: =IF(NOT(ISNUMBER('3_CONTINUATION SHEET'!Q41)),"",'3_CONTINUATION SHEET'!Q41) -> 218000 | J20: =IF(NOT(ISNUMBER(G20)),"",G20/H13) -> 0.12185579
C21: V/O, C/O | E21: 0 | F21: =IF(OR(NOT(ISNUMBER(G21)),NOT(ISNUMBER(E21))),"",G21-E21) -> 0 | G21: 0
C22: OTHERS | E22: 0 | F22: =IF(OR(NOT(ISNUMBER(G22)),NOT(ISNUMBER(E22))),"",G22-E22) -> 0 | G22: 0
C23: GROSS AMOUNT | D23: ② | E23: =IF(NOT(ISNUMBER(E20)),"",SUM(E20:E22)) -> 0 | F23: =IF(OR(NOT(ISNUMBER(G23)),NOT(ISNUMBER(E23))),"",G23-E23) -> 218000 | G23: =IF(NOT(ISNUMBER(G20)),"",SUM(G20:G22)) -> 218000 | H23: =H20+H21+H22 -> 0 | I23: =I20+I21+I22 -> 0
B24: ADV. REPAYMENT | C24: GROSS AMOUNT | D24: ③ | E24: 0 | F24: =IF(OR(NOT(ISNUMBER(G24)),NOT(ISNUMBER(E24))),"",G24-E24) -> 0 | G24: 0
B25: RETENTION | C25: =IF(OR(NOT(ISNUMBER('3_CONTINUATION SHEET'!U41)),NOT(ISNUMBER('3_CONTINUATION SHEET'!Q41)),'3_CONTINUATION SHEET'!Q41=0),0,'3_CONTINUATION SHEET'!U41/'3_CONTINUATION SHEET'!Q41) -> 0.05 | D25: ④ | E25: =IF(OR(NOT(ISNUMBER(E23)),NOT(ISNUMBER('1_PROGRESS PAYMENT'!$C$25))),"",IF(ISNUMBER('1_PROGRESS PAYMENT'!$H$41),'1_PROGRESS PAYMENT'!$H$41,ROUND(E23*'1_PROGRESS PAYMENT'!$C$25,2))) -> 0 | F25: =IF(OR(NOT(ISNUMBER(G25)),NOT(ISNUMBER(E25))),"",G25-E25) -> 10900 | G25: =IF(OR(NOT(ISNUMBER(G23)),NOT(ISNUMBER(C25))),"",ROUND(G23*C25,2)) -> 10900
B26: CONTRA CHARGES | C26: MATERIALS | E26: 0 | F26: =IF(OR(NOT(ISNUMBER(G26)),NOT(ISNUMBER(E26))),"",G26-E26) -> 0 | G26: 0
C27: LABOUR CHG | E27: 0 | F27: =IF(OR(NOT(ISNUMBER(G27)),NOT(ISNUMBER(E27))),"",G27-E27) -> 0 | G27: 0
C28: EQUIPMENT | E28: 0 | F28: =IF(OR(NOT(ISNUMBER(G28)),NOT(ISNUMBER(E28))),"",G28-E28) -> 0 | G28: 0
C29: OTHERS | E29: 0 | F29: =IF(OR(NOT(ISNUMBER(G29)),NOT(ISNUMBER(E29))),"",G29-E29) -> 0 | G29: 0
C30: SUB-TOTAL | D30: ⑤ | E30: =SUM(E26:E29) -> 0 | F30: =IF(OR(NOT(ISNUMBER(G30)),NOT(ISNUMBER(E30))),"",G30-E30) -> 0 | G30: =SUM(G26:G29) -> 0
B31: NET AMOUNT | D31: ⑥=①+②-③-④-⑤ | E31: =IF(OR(NOT(ISNUMBER(E23)),NOT(ISNUMBER(E25))),"",E19+E23-E24-E25-E30) -> 0 | F31: =IF(OR(NOT(ISNUMBER(G31)),NOT(ISNUMBER(E31))),"",G31-E31) -> 564900 | G31: =IF(OR(NOT(ISNUMBER(G23)),NOT(ISNUMBER(G25))),"",G19+G23-G24-G25-G30) -> 564900
B32: TAXES | D32: ⑦ | E32: 0 | F32: =IF(OR(NOT(ISNUMBER(G32)),NOT(ISNUMBER(E32))),"",G32-E32) -> 0 | G32: 0
C33: WITHHOLDING (less) | D33: ⑧ | E33: 0 | F33: =IF(OR(NOT(ISNUMBER(G33)),NOT(ISNUMBER(E33))),"",G33-E33) -> 0 | G33: 0
B34: NET RECEIPT | D34: ⑨=⑥+⑦-⑧ | E34: =IF(NOT(ISNUMBER(E31)),"",E31+E32-E33) -> 0 | F34: =IF(OR(NOT(ISNUMBER(G34)),NOT(ISNUMBER(E34))),"",G34-E34) -> 564900 | G34: =IF(NOT(ISNUMBER(G31)),"",G31+G32-G33) -> 564900
B36: =IF(NOT(ISNUMBER('3_CONTINUATION SHEET'!Q41)),"Check continuation sheet total.",IF(NOT(ISNUMBER(C25)),"Check retainage rate.",""))
B37: ADDITIONAL INPUTS (not printed on payment request)
B38: Application no. | F38: Period to
B39: Contractor address
F40: CCI job no.
F41: Previous retainage
B42: Previous retainage: leave blank to calculate from the current retainage rate; enter the approved prior amount to override.
B43: Progress %: enter previous cumulative in sheet 3 Q2, current cumulative in S2. Retainage %: C25 above.

Sheet 2_APPLICATION
A1: APPLICATION AND CERTIFICATE FOR PAYMENT
A2: TO GC | C2: =IF('1_PROGRESS PAYMENT'!$K$11="","",'1_PROGRESS PAYMENT'!$K$11) | F2: PROJECT: | G2: ='1_PROGRESS PAYMENT'!C12 -> HL-GA Battery Project | K2: APPLICATION #: | M2: =IF('1_PROGRESS PAYMENT'!$C$38="","",'1_PROGRESS PAYMENT'!$C$38)
K3: PERIOD TO: | M3: =IF('1_PROGRESS PAYMENT'!$H$38="","",'1_PROGRESS PAYMENT'!$H$38)
K4: CCI JOB #: | M4: =IF('1_PROGRESS PAYMENT'!$H$40="","",'1_PROGRESS PAYMENT'!$H$40)
K5: CONTRACT NO: | M5: =IF('1_PROGRESS PAYMENT'!$H$12="","",'1_PROGRESS PAYMENT'!$H$12)
K6: APPLICATION DATE: | M6: =IF('1_PROGRESS PAYMENT'!$C$10="","",'1_PROGRESS PAYMENT'!$C$10)
A7: FROM CONTRACTOR: | C7: =IF('1_PROGRESS PAYMENT'!$C$13="","",'1_PROGRESS PAYMENT'!$C$13) -> Nahshon MEP | K7: INVOICE #: | M7: =IF('1_PROGRESS PAYMENT'!$H$12="","",'1_PROGRESS PAYMENT'!F10)
C8: =IF('1_PROGRESS PAYMENT'!$C$39="","",'1_PROGRESS PAYMENT'!$C$39)
A13: CONTRACTOR'S APPLICATION FOR PAYMENT | G13: The undersigned Contractor certifies that to the best of the Contractor's knowledge,
A14: Application is made for payment, as shown below, in connection with the Contract. | G14: information and belief the Work covered by this Application for Payment has been
G15: completed in accordance with the Contract Documents, that all amounts have been
A16: 1 | B16: ORIGINAL CONTRACT SUM............................ | F16: ='3_CONTINUATION SHEET'!K41 -> 1789000 | G16: paid by the Contractor for Work for which previous Certificates for Payment were issued
G17: and payments received from the Owner, and that current payment shown herein is now due.
A18: 2 | B18: NET CHANGE BY CHANGE ORDERS............. | F18: 0
G19: Contractor: | H19: =IF('1_PROGRESS PAYMENT'!$C$13="","",'1_PROGRESS PAYMENT'!$C$13) -> Nahshon MEP
A20: 3 | B20: CONTRACT SUM TO DATE (LINE 1 & 2)......... | F20: =SUM(F16:F19) -> 1789000
G21: By: | L21: Date:
A22: 4 | B22: TOTAL COMPLETED & STORED TO DATE.... | F22: =IF(NOT(ISNUMBER('1_PROGRESS PAYMENT'!G23)),"",'1_PROGRESS PAYMENT'!G23) -> 218000 | G22: General Manager
G23: State of:
A24: 5 | B24: RETAINAGE: | G24: County of:
G25: Subscribed and sworn to before
B26: RETAINAGE ON COMPLETED WORK | E26: =IF(NOT(ISNUMBER('1_PROGRESS PAYMENT'!G25)),"",'1_PROGRESS PAYMENT'!G25) -> 10900 | G26: me this day of
B28: OTHER NET DEDUCTIONS / ADDITIONS | E28: ='1_PROGRESS PAYMENT'!G24+'1_PROGRESS PAYMENT'!G30+'1_PROGRESS PAYMENT'!G33-'1_PROGRESS PAYMENT'!G19-'1_PROGRESS PAYMENT'!G32 -> -357800 | G28: Notary Public:
G29: My Commission expires:
B30: TOTAL NET DEDUCTIONS | F30: =IF(NOT(ISNUMBER(E26)),"",SUM(E26,E28)) -> -346900
A32: 6 | B32: TOTAL EARNED LESS NET DEDUCTIONS | F32: =IF(OR(NOT(ISNUMBER(F22)),NOT(ISNUMBER(F30))),"",F22-F30) -> 564900 | G32: CERTIFICATE FOR PAYMENT
B33: (LINE 4 LESS LINE 5 TOTAL)
G34: In accordance with the Contract Documents, based on on-site observations and the data comprising
A35: 7 | B35: LESS PREVIOUS APPLICATIONS FOR PAYMENT | F35: =IF(NOT(ISNUMBER('1_PROGRESS PAYMENT'!E34)),"",'1_PROGRESS PAYMENT'!E34) -> 0 | G35: this application, the General Contractor certifies to the Owner that to the best of its knowledge,
B36: (LINE 6 FROM PRIOR CERTIFICATE) | G36: information and belief the work has progressed as indicated, the quality of the work is in accordance
G37: with the Contract Documents, and the Contractor is entitled to payment of the AMOUNT CERTIFIED.
A38: 8 | B38: CURRENT PAYMENT DUE......................................... | F38: =IF(OR(NOT(ISNUMBER(F32)),NOT(ISNUMBER(F35))),"",F32-F35) -> 564900
G39: AMOUNT CERTIFIED................................................................................................... | M39: =IF(NOT(ISNUMBER(F38)),"",F38) -> 564900
A40: 9 | B40: BALANCE TO FINISH, INCLUDING RETAINAGE | G40: (Attached explanation if amount certified differs from the amount applied for. Initial all figures on this
B41: (LINE 3 LESS LINE 6) | E41: =IF(NOT(ISNUMBER(F32)),"",F20-F32) -> 1224100 | G41: Application and on the continuation sheet that are changed to conform to the amount certified.)
G43: GENERAL CONTRACTOR
G45: By: | L45: Date:
G47: This certificate is not negotiable. The AMOUNT CERTIFIED is payable only to the Contractor named
G48: herein. Issuance, payment and acceptance of payment are without prejudice to any rights of the Owner
G49: of Contractor under this Contract.

Sheet 3_CONTINUATION SHEET
B1: CONTINUATION SHEET
T2: APPLICATION NO: | U2: 1
B3: APPLICATION AND CERTIFICATE FOR PAYMENT, | T3: APPLICATION DATE: | U3: 46285
B4: Containing Contractor's signed Certification, is attached. | T4: PERIOD TO: | U4: 09/01/26 ~ 09/30/26 (Forecast)
B5: In tabulations below, amounts are stated to the nearest dollar..
B6: Use column I on Contracts where variable retainage for line items may apply.
B8: A | C8: B | F8: C | L8: D | N8: E | P8: F | S8: G | U8: H
B9: ITEM NO. | C9: DESCRIPTION OF WORK | D9: Specification | E9: Unit | F9: CONTRACT VALUE (계약) | L9: WORK COMPLETED | P9: UP TO THIS BILL | R9: % | S9: BALANCE TO | U9: RETAINAGE
L10: PREVIOUS | N10: THIS PERIOD
F11: Quantity | G11: Material | H11: Labor | I11: Expense | J11: Unit Price | K11: Amount | L11: Quantity | M11: Amount | N11: Quantity | O11: Amount | P11: Quantity | Q11: Amount | S11: Quantity | T11: Amount
B12: 1 | C12: 건축공사 | E12: L/S | F12: 1 | K12: =TRUNC(SUM(K13:K21),2) -> 744998.1 | M12: =TRUNC(SUM(M13:M21),2) -> 0 | N12: =N49+N56+N65+N74+N84+N89+N103+N121+N169+N176+N195+N230+N264+N277+N288 -> 0 | O12: =TRUNC(SUM(O13:O21),2) -> 132127.08 | P12: =L12+N12 -> 0 | Q12: =TRUNC(SUM(Q13:Q21),2) -> 132127.08 | R12: =Q12/K12 -> 0.17735224 | T12: =TRUNC(SUM(T13:T21),2) -> 339684.89
C13: =C44 -> 1) TEMPORARY | E13: L/S | F13: 1 | K13: =K49 -> 37554 | M13: =M49 -> 0 | O13: =O49 -> 0 | Q13: =Q49 -> 0 | R13: =Q13/K13 -> 0 | T13: =T49 -> 37554
C14: =C50 -> 2) DOOR, WINDOW | E14: L/S | F14: 1 | K14: =K56 -> 25683.44 | M14: =M56 -> 0 | O14: =O56 -> 0 | Q14: =Q56 -> 0 | R14: =Q14/K14 -> 0 | T14: =T56 -> 25683.44
C15: =C57 -> 3) DRYWALL | E15: L/S | F15: 1 | K15: =K65 -> 94548.52 | M15: =M65 -> 0 | O15: =O65 -> 43909.46 | Q15: =Q65 -> 43909.46 | R15: =Q15/K15 -> 0.46441192 | T15: =T65 -> 50639.06
C16: =C66 -> 4) WALL FINISH | E16: L/S | F16: 1 | K16: =K74 -> 83277.19 | M16: =M74 -> 0 | O16: =O74 -> 0 | Q16: =Q74 -> 0 | R16: =Q16/K16 -> 0 | T16: =T74 -> 83277.19
C17: =C75 -> 5) FLOOR FINISH | E17: L/S | F17: 1 | K17: =K84 -> 67623.82 | M17: =M84 -> 0 | O17: =O84 -> 1859.6 | Q17: =Q84 -> 1859.6 | R17: =Q17/K17 -> 0.027499186 | T17: =T84 -> 65764.22
C18: =C85 -> 6) CEILING FINISH | E18: L/S | F18: 1 | K18: =K89 -> 45294 | M18: =M89 -> 0 | O18: =O89 -> 0 | Q18: =Q89 -> 0 | R18: =Q18/K18 -> 0 | T18: =T89 -> 45294
C19: =C90 -> 7) MISCELLANEOUS | E19: L/S | F19: 1 | K19: =K103 -> 193390.14 | M19: =M103 -> 0 | O19: =O103 -> 52972.812 | Q19: =Q103 -> 52972.812 | R19: =Q19/K19 -> 0.27391682 | T19: =T103 -> 16664.34
C20: =C104 -> 8) TOLIET WORKS | E20: L/S | F20: 1 | K20: =K121 -> 31845.22 | M20: =M121 -> 0 | O20: =O121 -> 0 | Q20: =Q121 -> 0 | R20: =Q20/K20 -> 0 | T20: =T121 -> 4751.72
C21: =C122 -> 9) CIVIL WORKS | E21: L/S | F21: 1 | K21: =K169 -> 165781.77 | M21: =M169 -> 0 | O21: =O169 -> 33385.211 | Q21: =Q169 -> 33385.211 | R21: =Q21/K21 -> 0.20138047 | T21: =T169 -> 10056.92
B22: 1.1 | C22: 설비공사 | E22: L/S | F22: 1 | K22: =TRUNC(SUM(K23:K31),2) -> 571271.38 | M22: =TRUNC(SUM(M23:M31),2) -> 0 | N22: =N296+N309+N339+N411+N439 -> 0 | O22: =TRUNC(SUM(O23:O31),2) -> 17851.5 | P22: =L22+N22 -> 0 | Q22: =TRUNC(SUM(Q23:Q31),2) -> 17851.5 | R22: =Q22/K22 -> 0.031248721 | T22: =TRUNC(SUM(T23:T31),2) -> 553419.87
C23: =C172 -> M0 General | D23: 74 | E23: L/S | F23: 1 | K23: =K176 -> 44319.55 | M23: =M176 -> 0 | O23: =O176 -> 0 | Q23: =Q176 -> 0 | R23: =Q23/K23 -> 0 | T23: =T176 -> 44319.55
C24: =C177 -> M1-1. Equipment | D24: 74 | E24: L/S | F24: 1 | K24: =K195 -> 31745.98 | M24: =M195 -> 0 | O24: =O195 -> 0 | Q24: =Q195 -> 0 | R24: =Q24/K24 -> 0 | T24: =T195 -> 31745.98
C25: =C196 -> M1-2. Duct Work | D25: 74 | E25: L/S | F25: 1 | K25: =K230 -> 121114.79 | M25: =M230 -> 0 | O25: =O230 -> 0 | Q25: =Q230 -> 0 | R25: =Q25/K25 -> 0 | T25: =T230 -> 121114.79
C26: =C231 -> M1-3-1. Domestic Water | D26: 74 | E26: L/S | F26: 1 | K26: =K264 -> 31293.987 | M26: =M264 -> 0 | O26: =O264 -> 6427.0832 | Q26: =Q264 -> 6427.0832 | R26: =Q26/K26 -> 0.20537758 | T26: =T264 -> 24866.904
C27: =C265 -> M1-3-2. Plumbing | E27: L/S | F27: 1 | K27: =K277 -> 8248.5435 | M27: =M277 -> 0 | O27: =O277 -> 8248.5435 | Q27: =Q277 -> 8248.5435 | R27: =Q27/K27 -> 1 | T27: =T277 -> 0
C28: =C278 -> M1-3-3 A/G NG Piping Work | E28: L/S | F28: 1 | K28: =K288 -> 7303.9099 | M28: =M288 -> 0 | O28: =O288 -> 3175.875 | Q28: =Q288 -> 3175.875 | R28: =Q28/K28 -> 0.43481847 | T28: =T288 -> 4128.035
C29: =C289 -> M1-4. Fire Protection Work | E29: L/S | F29: 1 | K29: =K296 -> 0 | M29: =M296 -> 0 | O29: =O296 -> 0 | Q29: =Q296 -> 0 | R29: =Q29/K29 -> #DIV/0! | T29: =T296 -> 0
C30: =C297 -> M1-5. Mechanical Demolition Work | E30: L/S | F30: 1 | K30: =K309 -> 26262.949 | M30: =M309 -> 0 | O30: =O309 -> 0 | Q30: =Q309 -> 0 | R30: =Q30/K30 -> 0 | T30: =T309 -> 26262.949
C31: =C310 -> M1-6. Civil WORK | E31: L/S | F31: 1 | K31: =K339 -> 300981.67 | M31: =M339 -> 0 | O31: =O339 -> 0 | Q31: =Q339 -> 0 | R31: =Q31/K31 -> 0 | T31: =T339 -> 300981.67
B32: 1.2 | C32: 전기공사 | E32: L/S | F32: 1 | K32: =TRUNC(SUM(K33:K38),2) -> 473550.88 | M32: =TRUNC(SUM(M33:M38),2) -> 0 | N32: =N458+N476+N485 -> 0 | O32: =TRUNC(SUM(O33:O38),2) -> 68365.84 | P32: =L32+N32 -> 0 | Q32: =TRUNC(SUM(Q33:Q38),2) -> 68365.84 | R32: =Q32/K32 -> 0.14436852 | T32: =TRUNC(SUM(T33:T38),2) -> 405185.04
C33: =C342 -> 01. POWER DISTRIBUTION WORK | D33: 74 | E33: L/S | F33: 1 | K33: =K411 -> 146204.14 | M33: =M411 -> 0 | O33: =O411 -> 68365.84 | Q33: =Q411 -> 68365.84 | R33: =Q33/K33 -> 0.46760536 | T33: =T411 -> 77838.3
C34: =C412 -> 02. MECHANICAL POWER WORK | D34: 74 | E34: L/S | F34: 1 | K34: =K439 -> 140971.86 | M34: =M439 -> 0 | O34: =O439 -> 0 | Q34: =Q439 -> 0 | R34: =Q34/K34 -> 0 | T34: =T439 -> 140971.86
C35: =C440 -> 03. Lighting WORK | E35: L/S | F35: 1 | K35: =K458 -> 63568.46 | M35: =M458 -> 0 | O35: =O458 -> 0 | Q35: =Q458 -> 0 | R35: =Q35/K35 -> 0 | T35: =T458 -> 63568.46
C36: =C459 -> 04. Receptacle WORK | D36: 74 | E36: L/S | F36: 1 | K36: =K476 -> 48825.62 | M36: =M476 -> 0 | O36: =O476 -> 0 | Q36: =Q476 -> 0 | R36: =Q36/K36 -> 0 | T36: =T476 -> 48825.62
C37: =C477 -> 05. INCIDENTAL EXPENSE | D37: 74 | E37: L/S | F37: 1 | K37: =K485 -> 73980.8 | M37: =M485 -> 0 | O37: =O485 -> 0 | Q37: =Q485 -> 0 | R37: =Q37/K37 -> 0 | T37: =T485 -> 73980.8
C38: =C486 -> 06. FIRE ALARM SYSTEM | D38: 74 | E38: L/S | F38: 1 | K38: =K489 -> 0 | M38: =M489 -> 0 | O38: =O489 -> 0 | Q38: =Q489 -> 0 | R38: =Q38/K38 -> #DIV/0! | T38: =T489 -> 0
C39: Round Off | K39: =-MOD(K12+K22+K32,1000) -> -820.36 | M39: =-MOD(M12+M22+M32,1000) -> 0 | O39: =-MOD(O12+O22+O32,1000) -> -344.42 | Q39: =-MOD(Q12+Q22+Q32,1000) -> -344.42
C41: TOTAL | K41: =K12+K22+K32+K39 -> 1789000 | M41: =M12+M22+M32+M39 -> 0 | O41: =O12+O22+O32+O39 -> 218000 | Q41: =Q12+Q22+Q32+Q39 -> 218000 | T41: =T12+T22+T32+T39 -> 1298289.8 | U41: =TRUNC(Q41*5%,2) -> 10900 | Z41: 1
B43: 0 | C43: 건축공사
...
